Workbook

Sheet dataset_overview
A1: dataset | B1: original_length | C1: sampled_length | D1: yfirferð
A2: arc_is_random_sample.csv | B2: 1116 | C2: 112 | D2: 3 | E2: alexandrainst/m_arc
A3: scala_is_random_sample.csv | B3: 1024 | C3: 102 | D3: 3
A4: iceEC_random_sample.csv | B4: 58239 | C4: 250 | D4: 3 | F4: yfirfarið | G4: =SUMIFS(C2:C13,D2:D13,">0") -> 1736 | H4: =G4/sum(C2:C13) -> 1 | J4: Yfirferðarkóðar
A5: nqii_random_sample.csv | B5: 2132 | C5: 213 | D5: 3 | F5: eftir | G5: =SUMIFS(C2:C13,D2:D13,"") -> 0 | H5: =G5/sum(C2:C13) -> 0 | J5: IC | K5: incomprehensible | L5: Skilgreining á IC: one of the following (anywhere in the example): severely flawed example, clearly/poorly machine-translated, incomprehensible
A6: icelandic_qa_random_sample.csv | B6: 2000 | C6: 200 | D6: 3 | J6: F | K6: flawed | L6: Skilgreining á F: one of the following: flawed example, contains spelling or grammatical errors, is wrong (e.g. wrong answer to a question)
A7: belebele_is_random_sample.csv | B7: 900 | C7: 90 | D7: 3 | F7: tvíyfirfarið | G7: =SUMIFS(C2:C13,D2:D13,">=2") -> 1736 | H7: =G7/sum(C2:C13) -> 1 | J7: OK | K7: okay
A8: multiwikiqa_is_random_sample.csv | B8: 5004 | C8: 250 | D8: 3 | F8: eftir | G8: =sum(C2:C13)-G7 -> 0 | H8: =G8/sum(C2:C13) -> 0
A9: arc_challenge_is_random_sample.csv | B9: 1119 | C9: 112 | D9: 3 | E9: Miðeind | J9: rater_1 | K9: Finnur
A10: mmlu_is_random_sample.csv | B10: 277 | C10: 28 | D10: 3 | F10: þríyfirfarið | G10: =SUMIFS(C2:C13,D2:D13,"3") -> 1736 | H10: =G10/sum(C2:C13) -> 1 | J10: rater_2 | K10: Steinunn
A11: winogrande_is_random_sample.csv | B11: 1088 | C11: 109 | D11: 3 | F11: eftir | G11: =SUM(C2:C13)-G10 -> 0 | H11: =G11/sum(C2:C13) -> 0 | J11: rater_3 | K11: Steinþór
A12: hellaswag_is_random_sample.csv | B12: 9368 | C12: 250 | D12: 3
A13: ged_is_random_sample.csv | B13: 200 | C13: 20 | D13: 3
A14: inflection_is_random_sample.csv | B14: 2400 | C14: 240
A15: iceling_random_sample.csv | B15: 1160 | C15: 116
A18: Dataset | B18: IC | C18: F | D18: OK | E18: Samanlagt | G18: Almennar aths.
A19: arc_is_random_sample.csv | B19: =countif(arc_is_random_sample!M2:M113,"IC") -> 44 | C19: =countif(arc_is_random_sample!M2:M113,"F") -> 50 | D19: =countif(arc_is_random_sample!M2:M113,"OK") -> 18 | E19: =SUM(B19:D19) -> 112 | F19: =if(E19=C2,"stemmir","stemmir ekki") -> stemmir | G19: Iðulega rangt fall í svörum m.v. spurningu, hvort í stað hvaða/hvert o.s.frv., skrýtin "íslensk" orð (handlinsa). Kynjamisræmi (Nemandi ... hún, Einstaklingur veiðir og mælir stóran fisk sem kallast lúða. Hún heldur ... þetta er ekki endilega óeðlilegt á íslensku, en samt ekki alveg eins og í ensku!), ákveðinn greinir í ensku sem á ekki endilega við í íslensku, í svörum eru stundum allar þrjár útgáfur af they á íslensku. "long hair" varð "hár" í íslenskri þýðingu og það skipti sköpum!
A20: scala_is_random_sample.csv | B20: =countif(scala_is_random_sample!D2:D114,"IC") -> 6 | C20: =countif(scala_is_random_sample!D2:D114,"F") -> 10 | D20: =countif(scala_is_random_sample!D2:D114,"OK") -> 86 | E20: =SUM(B20:D20) -> 102 | F20: =if(E20=C3,"stemmir","stemmir ekki") -> stemmir | G20: Aðallega Alþingisræður, i.e. talmál, </percent>, Gripið fram í, Forseti hringir, og setningar stundum réttar þrátt fyrir breytingar.
A21: iceEC_random_sample.csv | B21: =countif(iceEC_random_sample!F1:F251,"IC") -> 42 | C21: =countif(iceEC_random_sample!F1:F251,"F") -> 4 | D21: =countif(iceEC_random_sample!F1:F251,"OK") -> 204 | E21: =SUM(B21:D21) -> 250 | F21: =if(E21=C4,"stemmir","stemmir ekki") -> stemmir | G21: Ath. EuroEval pælir ekki í leiðréttum setningum, en stundum eru enn villur í leiðréttum setningum, réttar setningar eru stundum rangar og iceEC hefur nokkra villuflokka, style á t.d. illa við í svona prófi og hefur lítið með "grammatically correct" að gera.
A22: nqii_random_sample.csv | B22: =countif(nqii_random_sample!F1:F251,"IC") -> 41 | C22: =countif(nqii_random_sample!F1:F251,"F") -> 46 | D22: =countif(nqii_random_sample!F1:F251,"OK") -> 126 | E22: =SUM(B22:D22) -> 213 | F22: =if(E22=C5,"stemmir","stemmir ekki") -> stemmir | G22: stundum ekkert samhengi milli hins eiginlega samhengis og spurningar, og oft eru villur í spurningum (stafsetningar- og málfræðivillur) -- (STEINÞÓR): Spurningar um "hver er núverandi..." "Hvar spilar X í dag" o.s.frv. eru handónýtar í svona próf, nema textinn sé bara bull og það sé verið að spyrja úr honum. Annars getur rétt svar innan textans
A23: icelandic_qa_random_sample.csv | B23: =countif(icelandic_qa_random_sample!F2:F251,"IC") -> 8 | C23: =countif(icelandic_qa_random_sample!F1:F251,"F") -> 20 | D23: =countif(icelandic_qa_random_sample!F1:F251,"OK") -> 172 | E23: =SUM(B23:D23) -> 200 | F23: =if(E23=C6,"stemmir","stemmir ekki") -> stemmir
A24: belebele_is_random_sample.csv | B24: =countif(belebele_is_random_sample!L2:L91,"IC") -> 14 | C24: =countif(belebele_is_random_sample!L2:L91,"F") -> 51 | D24: =countif(belebele_is_random_sample!L2:L91,"OK") -> 25 | E24: =SUM(B24:D24) -> 90 | F24: =if(E24=C7,"stemmir","stemmir ekki") -> stemmir | G24: gögnin eiga að hafa verið þýdd af fagmönnum en bera þess yfirleitt ekki merki (vélþýðingarvillur/óeðlilegar villur koma fyrir...)
A25: multiwikiqa_is_random_sample.csv | B25: =countif(multiwikiqa_is_random_sample!F2:F251,"IC") -> 48 | C25: =countif(multiwikiqa_is_random_sample!F2:F251,"F") -> 84 | D25: =countif(multiwikiqa_is_random_sample!F2:F251,"OK") -> 118 | E25: =SUM(B25:D25) -> 250 | F25: =if(E25=C8,"stemmir","stemmir ekki") -> stemmir | G25: Fyrsta persóna í spurningum (Hvernig get ég orðið múslimi?), bullspurningar, villur í spurningum, spurningar samræmast ekki alltaf svari (t.d. út frá íslensku fallakerfi, svo sem "Hver var pabbi Fáfnis og Regins? Hreiðmars bónda" en kannski er ósanngjarnt að gagnrýna það (?), orðið 'pabbi' nær alltaf notað um föður einhvers
A26: arc_challenge_is_random_sample.csv | B26: =countif(arc_challenge_is_random_sample!E2:E251,"IC") -> 8 | C26: =countif(arc_challenge_is_random_sample!E2:E251,"F") -> 50 | D26: =countif(arc_challenge_is_random_sample!E2:E251,"OK") -> 54 | E26: =SUM(B26:D26) -> 112 | F26: =if(E26=C9,"stemmir","stemmir ekki") -> stemmir
A27: mmlu_is_random_sample.csv | B27: =countif(mmlu_is_random_sample!H2:H29,"IC") -> 17 | C27: =countif(mmlu_is_random_sample!H2:H29,"F") -> 9 | D27: =countif(mmlu_is_random_sample!H2:H29,"OK") -> 2 | E27: =SUM(B27:D27) -> 28 | F27: =if(E27=C10,"stemmir","stemmir ekki") -> stemmir
A28: winogrande_is_random_sample.csv | B28: =countif(winogrande_is_random_sample!F2:F110,"IC") -> 0 | C28: =countif(winogrande_is_random_sample!F2:F110,"F") -> 12 | D28: =countif(winogrande_is_random_sample!F2:F110,"OK") -> 97 | E28: =SUM(B28:D28) -> 109 | F28: =if(E28=C11,"stemmir","stemmir ekki") -> stemmir
A29: hellaswag_is_random_sample.csv | B29: =countif(hellaswag_is_random_sample!L2:L252,"IC") -> 247 | C29: =countif(hellaswag_is_random_sample!L2:L252,"F") -> 3 | D29: =countif(hellaswag_is_random_sample!L2:L252,"OK") -> 0 | E29: =SUM(B29:D29) -> 250 | F29: =if(E29=C12,"stemmir","stemmir ekki") -> stemmir
A30: ged_is_random_sample.csv | B30: =countif(ged_is_random_sample!C2:C21,"IC") -> 0 | C30: =countif(ged_is_random_sample!C2:C21,"F") -> 1 | D30: =countif(ged_is_random_sample!C2:C21,"OK") -> 19 | E30: =SUM(B30:D30) -> 20 | F30: =if(E30=C13,"stemmir","stemmir ekki") -> stemmir
A31: inflection_is_random_sample.csv
A32: iceling_random_sample.csv
A35: rater_2
A36: Dataset | B36: IC | C36: F | D36: OK | E36: Samanlagt
A37: arc_is_random_sample.csv | B37: =countif(arc_is_random_sample!L2:L131,"IC") -> 35 | C37: =countif(arc_is_random_sample!L2:L131,"F") -> 59 | D37: =countif(arc_is_random_sample!L2:L131,"OK") -> 18 | E37: =SUM(B37:D37) -> 112 | F37: =if(E37=C2,"stemmir","stemmir ekki") -> stemmir
A38: scala_is_random_sample.csv | B38: =countif(scala_is_random_sample!E2:E132,"IC") -> 0 | C38: =countif(scala_is_random_sample!E2:E132,"F") -> 12 | D38: =countif(scala_is_random_sample!E2:E132,"OK") -> 90 | E38: =SUM(B38:D38) -> 102 | F38: =if(E38=C3,"stemmir","stemmir ekki") -> stemmir
A39: iceEC_random_sample.csv | B39: =countif(iceEC_random_sample!H2:H269,"IC") -> 23 | C39: =countif(iceEC_random_sample!H2:H269,"F") -> 50 | D39: =countif(iceEC_random_sample!H2:H269,"OK") -> 177 | E39: =SUM(B39:D39) -> 250 | F39: =if(E39=C4,"stemmir","stemmir ekki") -> stemmir
A40: nqii_random_sample.csv | B40: =countif(nqii_random_sample!G2:G269,"IC") -> 37 | C40: =countif(nqii_random_sample!G2:G269,"F") -> 41 | D40: =countif(nqii_random_sample!G2:G269,"OK") -> 135 | E40: =SUM(B40:D40) -> 213 | F40: =if(E40=C5,"stemmir","stemmir ekki") -> stemmir
A41: icelandic_qa_random_sample.csv | B41: =countif(icelandic_qa_random_sample!G2:G269,"IC") -> 3 | C41: =countif(icelandic_qa_random_sample!G2:G269,"F") -> 26 | D41: =countif(icelandic_qa_random_sample!G2:G269,"OK") -> 171 | E41: =SUM(B41:D41) -> 200 | F41: =if(E41=C6,"stemmir","stemmir ekki") -> stemmir
A42: belebele_is_random_sample.csv | B42: =countif(belebele_is_random_sample!M2:M109,"IC") -> 8 | C42: =countif(belebele_is_random_sample!M2:M109,"F") -> 38 | D42: =countif(belebele_is_random_sample!M2:M109,"OK") -> 44 | E42: =SUM(B42:D42) -> 90 | F42: =if(E42=C7,"stemmir","stemmir ekki") -> stemmir
A43: multiwikiqa_is_random_sample.csv | B43: =countif(multiwikiqa_is_random_sample!G2:G269,"IC") -> 47 | C43: =countif(multiwikiqa_is_random_sample!G2:G269,"F") -> 86 | D43: =countif(multiwikiqa_is_random_sample!G2:G269,"OK") -> 117 | E43: =SUM(B43:D43) -> 250 | F43: =if(E43=C8,"stemmir","stemmir ekki") -> stemmir
A44: arc_challenge_is_random_sample.csv | B44: =countif(arc_challenge_is_random_sample!F2:F269,"IC") -> 7 | C44: =countif(arc_challenge_is_random_sample!F2:F269,"F") -> 51 | D44: =countif(arc_challenge_is_random_sample!F2:F269,"OK") -> 54 | E44: =SUM(B44:D44) -> 112 | F44: =if(E44=C9,"stemmir","stemmir ekki") -> stemmir
...

Sheet arc_is_random_sample
A1: id | B1: answer | C1: instruction | D1: option_a | E1: option_b | F1: option_c | G1: option_d | H1: option_e | I1: rater_3 | J1: rater_3 athugasemd | K1: rater_3_not_pedantic | L1: rater_2 | M1: rater_1
A2: ARC-Challenge/train/Mercury_7016625 | B2: A | C2: Í berghringrásinni hefst veðrun og rof sem leiðir til myndunar | D2: setlögum. | E2: magma. | F2: jarðefni. | G2: kristalla. | I2: F | J2: vitlaus beyging, annars OK | K2: OK | L2: F | M2: F
A3: ARC-Challenge/train/Mercury_7041248 | B3: D | C3: Tveimur efnum er blandað saman í bikarglasi sem er í ísvatnsbaði. Ísinn í vatninu bráðnar þegar íðefnin hvarfast í eina mínútu. Hvers konar hvarf á sér stað? | D3: innvarma, þar sem orka er tekin upp | E3: innvarma, þar sem orka er losuð | F3: útvarma, þar sem orka er tekin upp | G3: útvarma, þar sem orka er leyst út | I3: F | J3: það heitir útvermið | K3: OK | L3: F | M3: OK
A4: ARC-Challenge/train/Mercury_SC_416456 | B4: A | C4: Einfruma lífvera getur gert allt sem fruma úr fjölfrumu lífveru getur gert nema | D4: sérhæfa sig. | E4: fjölga sér. | F4: nota orku. | G4: búa til prótein. | I4: F | J4: sérhæft sig | K4: OK | L4: F | M4: F
A5: ARC-Challenge/train/ACTAAP_2008_5_7 | B5: A | C5: Hvað brjóta frumur niður til að framleiða orku? | D5: matvæli | E5: vatn | F5: chlorophyll | G5: koltvísýringur | I5: F | J5: samt skrítið að tala um "matvæli" - eru ekki ensími sem brjóta þau niður og svo nýta frumur kolvetni, fitu eða prótín? | K5: OK | L5: F | M5: F
A6: ARC-Challenge/train/MCAS_2008_5_5633 | B6: B | C6: Nemendur vilja planta sítrónutré í skólann sinn en kuldatíð í Massachusetts myndi drepa tréð. Hver af eftirfarandi er besta lausnin á þessu vandamáli? | D6: að planta nokkrum sítrónutrjám saman í röð | E6: bygging gróðurhúss til að hýsa sítrónutréð | F6: að gefa sítrónutrénu auka áburð á veturna | G6: að binda staur við sítrónutréð til stuðnings yfir veturinn | I6: F | J6: "í skólann sinn"!! | K6: OK | L6: F | M6: F
A7: ARC-Challenge/train/MCAS_2005_8_4 | B7: B | C7: Hvert af eftirfarandi er dæmi um líkamlega breytingu? | D7: kveikja eldspýtu | E7: brjóta glas | F7: brennsla bensíns | G7: ryðfylling járns | I7: F | J7: "líkamlega" á ekki við hér | L7: IC | M7: F
A8: ARC-Challenge/train/ACTAAP_2008_7_3 | B8: C | C8: Hvaða spurningu er líklegast að hægt sé að svara með vísindalegri rannsókn? | D8: Hver verður sigurvegari næsta happdrættis? | E8: Hvaða knattspyrnulið vinnur næsta leik? | F8: Hvert er ljósmagnið sem þarf til að rækta tómata? | G8: Hvaða fjórar fuglafjaðrir eru fallegastar á litinn? | I8: OK | L8: OK | M8: OK
A9: ARC-Challenge/train/MEA_2011_8_3 | B9: D | C9: Á hvaða stað á jörðinni er sólbirtan minnst þann 22. desember? | D9: Miðja | E9: Flórída | F9: Maine | G9: Norðurpóllinn | I9: F | J9: við notum "sólarljós" en ekki "sólbirta" | K9: OK | L9: F | M9: F
A10: ARC-Challenge/train/MEA_2016_8_1 | B10: C | C10: Refur fæddi afkvæmi sem höfðu betri heyrn en flestir refir. Hvernig gæti þessi litla breyting líklegast leitt til afkomenda sem eru frábrugðnir upprunalega refnum? | D10: Ræsir sem hafa betra heyrnarskyn geta stökkbreyst oftar en aðrir refir. | E10: Það má veiða oftar refi sem hafa betra heyrnarskyn. | F10: Með tímanum gætu afkomendur þessa refs heyrt betur og veitt bráð en aðrir refir. | G10: Með tímanum geta afkomendur þessa refs orðið útdauðir. | I10: OK | J10: A-svarið er gallað og upphafið á C: "Með tímanum" er óþarfur og mögulega truflandi | L10: F | M10: IC
A11: ARC-Challenge/train/NYSEDREGENTS_2006_8_26 | B11: C | C11: Þó að breytingar á fjölfrumutegundum taki yfirleitt mörg þúsund ár, þá taka sumar bakteríutegundir miklum breytingum á örfáum árum. Ein ástæðan fyrir þessum mun er sú að þessar bakteríur | D11: eru smásæjar | E11: innihalda ekki DNA | F11: fjölga sér mjög fljótt | G11: valda smitsjúkdómum | I11: OK | J11: "fljótt" ætti að vera "ört" | L11: OK | M11: OK
A12: ARC-Challenge/train/Mercury_7206535 | B12: C | C12: Í fjölfrumulífverum gegna mismunandi byggingar mismunandi hlutverki. Hvaða hlutverki gegnir laufplanta? | D12: að taka til sín mat | E12: að framleiða blóm | F12: gleypir ljós | G12: fræsuðugerð | I12: IC | J12: Laufblöð vinna orku úr sólarljósi, koltvísýringi og vatni. Ég hef aldrei heyrt að hlutverk laufplantna sé að "gleypa ljós" | K12: F | L12: F | M12: IC
A13: ARC-Challenge/train/Mercury_SC_401591 | B13: D | C13: Sólarsellur taka til sín orku frá sólinni. Til þess að nýta þessa orku til að knýja heimilistæki þurfa sólarsellur að umbreyta upptekinni orku í | D13: hiti. | E13: ljós. | F13: geislun. | G13: rafmagn. | I13: OK | J13: beyging samt röng á valmöguleika A | L13: F | M13: F
A14: ARC-Challenge/train/Mercury_183750 | B14: A | C14: Í hvaða sviðsmynd hér á eftir er líklegast að náttúruval eigi sér stað? | D14: Loftslagsbreytingar hafa smám saman aukist í aldaraðir | E14: stórfelld eyðilegging búsvæða | F14: hröð og mikil loftslagsbreytingar | G14: tafarlaust tap á frumfæðugjöfum | I14: OK | J14: Svar C er gallað | L14: F | M14: F
A15: ARC-Challenge/train/Mercury_SC_400300 | B15: B | C15: Hvort þessara tækja væri best að nota þegar skordýr eru skoðuð á vettvangi? | D15: áttaviti | E15: handlinsa | F15: smásjá | G15: hitamælir | I15: F | J15: Er "handlinsa" það sama og stækkunargler? | K15: OK | L15: F | M15: F
A16: ARC-Challenge/train/Mercury_SC_LBS10271 | B16: B | C16: Hvað er það sem einkennir plöntur og dýr? | D16: Plöntur þurfa ekki á steinefnum að halda og dýrin líka. | E16: Plöntur framleiða sína eigin fæðu og dýr ekki. | F16: Plöntur framleiða ekki súrefni og það gera dýrin líka. | G16: Plöntur þurfa sólarljós og dýr ekki. | I16: F | J16: Öll svör eru einkennilega orðuð | K16: OK | L16: IC | M16: F
A17: ARC-Challenge/train/Mercury_SC_400119 | B17: A | C17: Hvaða breyting verður á vírum rafrásar sem virkar eðlilega? | D17: Vírinn hlýnar | E17: Vírinn mun missa hluta af massa sínum. | F17: Vírinn myndar rafsvið. | G17: Vírinn myndar nýja kristalbyggingu. | I17: F | J17: Vírinn "hlýnar" ekki. Hann hitnar. | K17: OK | L17: F | M17: OK
A18: ARC-Challenge/train/Mercury_7056613 | B18: D | C18: Þegar bílvél er gangsett er bensíni blandað saman við loft og brennt. Varmi, hljóð og efnaafurðir losna. Hvort þessara þátta helst stöðugt í gangi vélarinnar? | D18: massa efnasambanda sem finnast í vélinni | E18: hversu mikill hiti er í vélinni | F18: heildarmassi bensíns | G18: heildarorkumagnið | I18: F | J18: Klúðurslega orðað, en mögulega hægt að ramba á rétt svar. | K18: OK | L18: F | M18: F
A19: ARC-Challenge/train/Mercury_7181668 | B19: C | C19: Daffodils eru plöntur sem geta bæði framkvæmt kynlausa og kynlausa æxlun. Hvernig nýtist daffodil stofninn betur við að æxlast kynlaust en kynlaus? | D19: Hún getur fjölgað sér hraðar. | E19: Það getur aðlagast umhverfi sínu hraðar. | F19: Það getur aukið fjölbreytni arfgengra eiginleika. | G19: Það getur eytt óheppilegum eiginleikum úr genamengi. | I19: IC | J19: Daffodils er ekki íslenska | K19: F | L19: IC | M19: IC
A20: ARC-Challenge/train/AKDE&ED_2012_8_14 | B20: A | C20: Einstaklingur fellir lifandi eikartré. Einstaklingurinn brennir viðinn úr eikartrénu til að sjóða vatn. Hvaða röð raðar rétt þeim orkuumbreytingum sem áttu sér stað frá lifandi trénu til sjóðunar vatns? | D20: ljósorka - efnaorka - varmaorka | E20: varmaorka - efnaorka - ljósorka | F20: efnaorka - vélræn orka - rafmagnsorka | G20: rafmagns-vélræn-efnaorka | I20: F | J20: Skringilega orðað, en hægt að skilja | K20: OK | L20: IC | M20: F
A21: ARC-Challenge/train/Mercury_SC_LBS10907 | B21: B | C21: Á hvaða tímaskeiði tunglsins gæti sólmyrkvi átt sér stað? | D21: full | E21: ný | F21: ársfjórðung | G21: hálfmáni | I21: F | J21: Það er talað um kvartilaskipti á tunglinu. Ekkert af þeim heitir ársfjórðungur og raunar ekki hálfmáni heldur. Svarið er samt þannig að hægt er að ramba á það. En varla hægt að tala um fjóra valmöguleika, sem er gegnumgangandi galli í þessu prófi. | L21: F | M21: IC
A22: ARC-Challenge/train/MEA_2014_8_6 | B22: B | C22: Bolta er varpað úr mismunandi hæð. Þegar bolta er varpað úr hæstu hæð þá er mesti hávaðinn eða titringurinn þegar hann lendir á jörðinni. Hver er besta skýringin á því að boltinn er með mesta hávaðann? | D22: Loftið þrýstir meira niður og boltinn fer hraðar. | E22: Þyngdaraflið togar í lengri tíma og boltinn fer hraðar. | F22: Boltinn þyngist og fer hraðar. | G22: Boltinn er að hitna og fer hraðar. | I22: OK | J22: mætti samt orða betur | L22: F | M22: F
A23: ARC-Challenge/train/LEAP__5_10318 | B23: D | C23: Miguel var að gera tilraun. Hann skrifaði eftirfarandi setningar í stílabókina sína: Byrjunarhitastig vatnsins var 10 gráður á Celsíus. Hlutur sem var 5 grömm að þyngd var settur í vatnið. Hitastig vatnsins hækkaði í 15 gráður. Hluturinn þarf að hafa verið heitari en 10 gráður. Í hvaða setningu ályktaði Miguel? | D23: setning 1 | E23: 2. setning | F23: 3. setning | G23: setning 4 | I23: OK | J23: ósamræmi í orðalagi svara, en skiptir ekki máli hér | L23: F | M23: F
A24: ARC-Challenge/train/MCAS_2008_8_5608 | B24: C | C24: Ef ný lífvera fyndist, hvaða af eftirfarandi yrði þá líklegast notað til að flokka hana í viðeigandi ríki? | D24: litur lífverunnar | E24: náttúrulegt búsvæði lífverunnar | F24: uppbyggingu líffærakerfis lífverunnar | G24: staðsetningin þar sem lífveran fannst | I24: OK | J24: orðalag | L24: F | M24: F
A25: ARC-Challenge/train/CSZ20740 | B25: B | C25: Hversu langan tíma tekur reiðhjól að fara 100 m vegalengd á meðalhraðanum 2 m/s? | D25: 0.0 | E25: s B 50 s | F25: 100 sek | G25: 200 s | I25: F | J25: Svör ekki stöðluð og rétta svarið skrítið | K25: OK | L25: F | M25: F
A26: ARC-Challenge/train/Mercury_7185448 | B26: B | C26: Kveikja eldspýtu og baka köku eru tvær aðgerðir sem fela í sér efnabreytingar. Hvers vegna eru þessar aðgerðir taldar efnabreytingar? | D26: Þær breyta ástandi efnisins. | E26: Þau búa til ný efni. | F26: Þeir breyta um magn. | G26: Þau skapa orku. | I26: F | J26: Upphafið | L26: F | M26: IC
A27: ARC-Challenge/train/Mercury_7268293 | B27: D | C27: Hvernig rata fræsprotar sem grafnir eru í algjöru myrkri í jarðveginum upp á yfirborð jarðvegsins? | D27: Þeir vaxa í átt að ljósi. | E27: Þau vaxa í átt að yfirborðshita. | F27: Þau vaxa á móti berggrunninum. | G27: Þau vaxa í andstöðu við stefnu þyngdaraflsins. | I27: OK | J27: "Þeir" en ekki "Þau" í svarinu | L27: OK | M27: IC
A28: ARC-Challenge/train/Mercury_7166093 | B28: B | C28: Plöntur geta komið í veg fyrir rof eða stuðlað að rofi. Hvert er dæmið um hvernig plöntur gætu stuðlað að rofi? | D28: Plöntur hægja á afrennsli vatns og jarðvegs. | E28: Rótar plöntunnar vaxa í bergi og brjóta það. | F28: Rætur plantna halda jarðveginum á sínum stað gegn vindi. | G28: Plöntur brjóta niður áhrif regndropa áður en þeir lenda í jarðveginum. | I28: F | J28: Í rétta svarinu stendur "Rótar" en ekki "Rætur" | L28: F | M28: F
A29: ARC-Challenge/train/Mercury_SC_LBS10674 | B29: D | C29: Hvert af eftirfarandi er dæmi um efnabreytingu? | D29: ský myndast | E29: sykur sem leysist upp | F29: vatnsfrysting | G29: kerti brennur | I29: OK | J29: Fáir myndu samt tala um "vatnsfrystingu" | L29: OK | M29: F
A30: ARC-Challenge/train/NYSEDREGENTS_2009_8_20 | B30: D | C30: Einn mikilvægur munur á lifandi og ólifandi er sá að aðeins lifandi hlutir hafa | D30: Efnasambönd | E30: þættir | F30: sameindir | G30: frumur | I30: F | J30: "ólifandi"? | L30: IC | M30: F
A31: ARC-Challenge/train/Mercury_SC_405303 | B31: C | C31: Hvaða vatnsform er líklegast að komi fram þegar hitastig er undir frostmarki? | D31: þoka | E31: rigning | F31: snjór | G31: skýjað | I31: OK | J31: "vatnsform" er samt bara bull | L31: OK | M31: F
A32: ARC-Challenge/train/Mercury_7245070 | B32: B | C32: Hvaða matvörur er hægt að brjóta niður að mestu í amínósýrur? | D32: Spagettí-núðlur | E32: Hamborgarabrauð | F32: eplahneppi | G32: gúrkusneiðar | I32: IC | J32: Hvað er "eplahneppi"? Inniheldur brauð meira af amínósýrum en spagettí? Getur verið að hér eigi bara að vera hamborgari, en ekki hamborgarabrauð? | L32: F | M32: F
A33: ARC-Challenge/train/Mercury_7284060 | B33: B | C33: Vampírufinkur á Galapagos eyjum kroppa aðra fuglategund, bláfættan bauga, þar til finkurnar sárbæna. Síðan drekka finkurnar blóð bauga. Vísindamenn halda að fyrir mörgum kynslóðum hafi finkurnar kroppað pöddur af bauga og hegðunin þróast í það sem hún er í dag. Hvor staðhæfingin lýsir best sambandi fugla fyrir mörgum kynslóðum og sambandinu í dag? | D33: Gamla sambandið var sníkjudýralegt. Nýja sambandið er gagnkvæmt. | E33: Gamla sambandið var gagnkvæmt en nýja sambandið er sníkjudýr. | F33: Bæði samböndin eru sníkjudýr. | G33: Bæði samböndin eru gagnkvæm. | I33: IC | J33: illskiljanleg spurning | K33: F | L33: IC | M33: IC
A34: ARC-Challenge/train/Mercury_416673 | B34: A | C34: Margir þættir hafa áhrif á heilsu fólks. Hvaða hugtak lýsir best mataræði og hreyfingu hjá flestum fullorðnum? | D34: lífsstílsval | E34: umhverfisþáttur | F34: erfðafræðileg tilhneiging | G34: hegðun sem er ávísuð af lækni | I34: IC | J34: Bein þýðing úr ensku sem verður frekar torskilin á íslensku | L34: OK | M34: F
A35: ARC-Challenge/train/NYSEDREGENTS_2011_4_13 | B35: C | C35: Nemandi sem hjólar sér að hann fer hraðar yfir sléttan veg en torfæran. Það gerist vegna þess að slétti vegurinn hefur | D35: minni þyngdarafl | E35: meiri þyngdarafl | F35: minni núningur | G35: meiri núningur | I35: OK | J35: Slétti vegurinn "hefur" ekki minni núning. En það er kannski minni núningur á milli hjólsins og vegarins á slétta veginum. | K35: F | L35: F | M35: IC
A36: ARC-Challenge/train/MCAS_1998_8_5 | B36: A | C36: Hvor staðhæfingin um ljóstillífun og öndun er sönn? | D36: Ljóstillífun geymir orku og öndun losar orku. | E36: Öndunin geymir orku og ljóstillífun losar orku. | F36: Ljóstillífun og öndun eru sama ferlið. | G36: Ljóstillífun og öndun hafa ekkert með orku að gera. | I36: OK | L36: F | M36: OK
A37: ARC-Challenge/train/Mercury_7030083 | B37: B | C37: Daginn áður en bekkurinn fer í tilraunastofu minnir kennari þeirra á að fara ekki í opna skó í skólann daginn eftir. Hvaða rök útskýra beiðni kennarans best? | D37: til að koma í veg fyrir að spilliefni leki | E37: til að koma í veg fyrir áverka á tám eða fótum | F37: til að koma í veg fyrir að þeir verði þreyttir á fótum | G37: að halda þeim kyrrum ef áföll dynja yfir | I37: F | J37: orðalag skrítið | L37: F | M37: F
A38: ARC-Challenge/train/MEA_2010_8_7 | B38: B | C38: Hvert af eftirfarandi er lengst frá jörðinni? | D38: Halastjarna Halleys | E38: Andromeda vetrarbrautin | F38: Neptúnus | G38: Sólin | I38: OK | L38: OK | M38: F
A39: ARC-Challenge/train/Mercury_184345 | B39: C | C39: Hvert af eftirfarandi er besta sönnun þess að landsvæði hafi eitt sinn verið hulið jökli? | D39: kalksteinsskálar | E39: sjávarjarðefni | F39: slit á yfirborðsgrjóti | G39: flagnandi bergflekar | I39: OK | L39: OK | M39: F
A40: ARC-Challenge/train/Mercury_7071943 | B40: C | C40: Hvaða jarðvegsþáttur hefur minnsta getu til að halda vatni? | D40: silt | E40: leir | F40: sandi | G40: humus | I40: F | J40: jarðvegsgerð. Rétta svarið er vitlaust beygt. Valmöguleikar 1 og 4 eru óþýddir. | L40: F | M40: F
...

Sheet scala_is_random_sample
A1: text | B1: corruption_type | C1: label | D1: rater_1 | E1: rater_2 | F1: rater_3
A2: Núna þurfum við að fá meira að láni í nafni sanngirni. | C2: correct | D2: OK | E2: OK | F2: OK
A3: Hvers vegna erum við ekki með lögin þannig að hver sem opinberlega hæðist að, rógber, smánar og ógnar manni og svo framvegis án tillits Forseti hringir. til nokkurs skapaðar hlutar sæti refsingu? | C3: correct | D3: OK | E3: OK | F3: OK
A4: Alþingi gert getur hitt og þetta. | B4: flip_neighbours | C4: incorrect | D4: OK | E4: OK | F4: OK
A5: Hitt er miklu stærra mál sem við erum ekki búin að afgreiða og við eigum ekki að afgreiða með þessu, það er hvar línurnar eiga að liggja, af því að við setjum ekki bara venjulegan verðmiða á það. | C5: correct | D5: OK | E5: OK | F5: OK
A6: Að öðru leyti við ég þakka svör utanríkisráðherra í dag og hrósa honum aftur og hvetja hann áfram til að standa vörð um NATO. | C6: correct | D6: IC | E6: F | F6: F
A7: Niðurstaðan varð sú að hvetja ráðherra til að halda áfram og hefur hún móttekið þau skilaboð. | C7: correct | D7: OK | E7: OK | F7: OK
A8: Hann er látinn fylgja landslaginu eins mikið og mögulegt er til þess að sé hann sem minnst áberandi. | B8: flip_neighbours | C8: incorrect | D8: OK | E8: OK | F8: OK
A9: Virðulegi forseti. Hvað það varðar að markmiðið sé ljóst og tvíþætt ég hélt nú að ég væri að gera stuðningsmönnum frumvarpsins greiða með því að kalla það óljóst. | C9: correct | D9: F | E9: F | F9: OK
A10: Maður býr við verðbólgu, maður einhvern veginn venst því. | C10: correct | D10: OK | E10: OK | F10: OK
A11: og samgöngu nefnd lagði gríðarlega vinnu í málið. | B11: delete | C11: incorrect | D11: F | E11: F | F11: F
A12: Guðni Valur Guðnason kringlukastari úr ÍR náði sínum besta árangri á árinu þegar hann kastaði 60,72 m Vormóti á UFA á Þórsvelli á Akureyri í dag. | B12: flip_neighbours | C12: incorrect | D12: OK | E12: OK | F12: OK
A13: Virðulegi forseti. Það er svo sem ekki mikið eftir að ræða í sjálfu hvað viðkemur þessu tiltekna máli. | B13: delete | C13: incorrect | D13: OK | E13: OK | F13: F
A14: Varðandi það sem hv. þingmaður spurði um og ég nefndi sem dæmi um nokkra hluti sem eru mikið á skjön við annað og andann í þessu frumvarpi sem er ekki upplífgandi að stærstum hluta til nema í einstökum tilvikum. | C14: correct | D14: OK | E14: OK | F14: OK
A15: Það var að sjálfsögðu erfitt fyrir margra hluta sakir og auðvitað greindi menn á um það hvernig ætti að skipta takmarkaðri auðlind. | C15: correct | D15: OK | E15: OK | F15: OK
A16: Leikur Íslands og Danmerkur hefst klukkan 19:15 og verður sýndur á RÚV 2. | C16: correct | D16: OK | E16: OK | F16: OK
A17: Það þarf ekki alltaf greiningartæki til þess að sjá hvað er helsta vinnuafl ríkisins, til að mynda á landsbyggðinni eða innan eða menntakerfisins. | B17: delete | C17: incorrect | D17: OK | E17: OK | F17: OK
A18: Bryndísi Rún Hansen tókst ekki að sér tryggja sæti í undanúrslitum 100 m skriðsunds kvenna. | B18: flip_neighbours | C18: incorrect | D18: OK | E18: OK | F18: OK
A19: Svo er hitt, að það er kannski ekki þingmannsstarf að meta hversu mikið mál það væri. | C19: correct | D19: OK | E19: OK | F19: OK
A20: Hefði áætlunin, ef hún hefði verið samþykkt, komið í veg fyrir þær tillögur sem voru í fjárlagafrumvarpinu og ákveðin voru atlaga að konum? | B20: flip_neighbours | C20: incorrect | D20: OK | E20: OK | F20: OK
A21: Það er mun ódýrara að borga þá bara fyrir viðtalið á greiningunni. | C21: correct | D21: OK | E21: OK | F21: F
A22: Störfunum fjölgar jú og fleiri hendur vinna þau en arðbærnin og hagkvæmnin er ekki sama sú. | B22: flip_neighbours | C22: incorrect | D22: OK | E22: OK | F22: OK
A23: Lengra svarið er að þegar kemur að fjarskiptasjóði og nettengingu úti á landi þá finnst mér það óhjákvæmilega svolítið eins og að skilja fólk eftir símalaust eða ég ætla ekki að segja vatnslaust kannski en símalaust og jafnvel rafmagnslaust þegar það er netlaust eða með það lélega tengingu að geti ekki gert það sem það þarf að gera. | B23: delete | C23: incorrect | D23: OK | E23: OK | F23: F
A24: Mig langar til þess að minna hv. þm. Pál Jóhann Pálsson á þegar hann segir að hér sé aðeins deilt um útfærslu og hversu mikið útgerðin þoli að það er í raun og veru enginn sérstakur ágreiningur um það í þjóðfélaginu. | C24: correct | D24: OK | E24: OK | F24: OK
A25: hún í undanúrslit keppir hún í þeim á fimmtudag klukkan 16: 50. | B25: delete | C25: incorrect | D25: OK | E25: OK | F25: OK
A26: Gripið fram í: Svo er praxísinn Já, svo er það alls konar praxísinn og jafnvægið þar á milli, það fer eftir því hvað verið er að tala um o. s. frv. En mér finnst þetta einhvern veginn vera það versta úr báðum hugmyndum. | B26: delete | C26: incorrect | D26: IC | E26: F | F26: OK
A27: Ef þessi lög eiga að standast lög um tjáningarfrelsi vil ég því upp, virðulegi forseti, að það sé eitthvað mikið að því hvernig við lítum á tjáningarfrelsið. | B27: delete | C27: incorrect | D27: OK | E27: OK | F27: OK
A28: Núna skilst mér að það séu fleiri en 300 nemendur í skólanum en menn töluðu ávallt um í kringum 250. | C28: correct | D28: OK | E28: OK | F28: OK
A29: Þetta er besti tími sem Bryndís hefur nokkurn tímann synt á í greininni. | C29: correct | D29: OK | E29: OK | F29: OK
A30: Norska kvennalandsliðið í handbolta vann tíu marka sigur á Hvít-Rússum í Minsk í gær 32 22 og tryggði sér þannig sæti á EM sem haldið verður í Svíþjóð í desember. | C30: correct | D30: OK | E30: OK | F30: OK
A31: Þess vegna spyr ég, eðlilega: Hvað hafa menn verið að gera þessi tvö ár ef ekki er meira kjöt á beinunum en raun ber vitni? | C31: correct | D31: OK | E31: OK | F31: OK
A32: Alþingi getur gert hitt og þetta. | C32: correct | D32: OK | E32: OK | F32: OK
A33: Héldu menn virkilega að það yrði með öðrum hætti? | C33: correct | D33: OK | E33: OK | F33: OK
A34: Það efast enginn um mikilvægi þess að leggja fram kerfisáætlun en það er ekki sama hvernig það er gert og við þurfum að vanda okkur betur. | C34: correct | D34: OK | E34: OK | F34: OK
A35: Ég tek hins vegar undir með hv. þingmanni, við megum ekki tala um að þetta verkefni fari illa. | C35: correct | D35: OK | E35: OK | F35: OK
A36: Það er bara hluti af hinum föstu tekjusamskiptum ríkis og sveitarfélaga og hefur verið svo mjög lengi. | C36: correct | D36: OK | E36: OK | F36: OK
A37: En hvað er hér á dagskrá? | C37: correct | D37: OK | E37: OK | F37: OK
A38: Það er skýr munur á umhverfi nútímans, árið 2013, frá því sem var 1990, munurinn er svo yfirþyrmandi og skýr að það blasir við að endurskoða þarf náttúruverndarlög með hliðsjón af því. | C38: correct | D38: OK | E38: OK | F38: OK
A39: Gleymum því ekki að við komum úr sárustu fátækt Evrópu fyrir rúmum 100 árum. | C39: correct | D39: OK | E39: OK | F39: OK
A40: Gylfi Þór Sigurðsson og Ögmundur Kristinsson séu líklega þeir bestu í hópnum. | C40: correct | D40: OK | E40: OK | F40: F
...

Sheet iceEC_random_sample
A1: idx | B1: sentence | C1: errors | D1: has_error | E1: corrected_sentence | F1: rater_1 | G1: leiðrétting | H1: rater_2 | I1: rater_3
A2: 54106 | B2: ['Kannski' 'er' 'þessi' 'fullyrðing' 'þröngsýn' 'en' 'ef' 'prestur' 'er' 'spurður' 'afhverju' 'samkynhneigt' 'fólk' 'má' 'ekki' 'giftast' 'þá' 'svarar' 'hann' '„' 'vegna' 'þess' 'að' 'hjónband' 'getur' 'ekki' 'átt' 'sér' 'stað' 'nema' 'á' 'milli' 'karls' 'og' 'konu' '“' '.'] | C2: [array([], dtype=object) array([], dtype=object) array([], dtype=object) array([], dtype=object) array([], dtype=object) array([], dtype=object) array([], dtype=object) array([], dtype=object) array([], dtype=object) array([], dtype=object) array(['orthography', 'orthography'], dtype=object) array([], dtype=object) array([], dtype=object) array([], dtype=object) array([], dtype=object) array([], dtype=object) array([], dtype=object) array([], dtype=object) array([], dtype=object) array([], dtype=object) array([], dtype=object) array([], dtype=object) array([], dtype=object) array([], dtype=object) array([], dtype=object) array([], dtype=object) array([], dtype=object) array([], dtype=object) array([], dtype=object) array([], dtype=object) array([], dtype=object) array([], dtype=object) array([], dtype=object) array([], dtype=object) array([], dtype=object) array([], dtype=object) array([], dtype=object)] | D2: True | E2: ['Kannski' 'er' 'þessi' 'fullyrðing' 'þröngsýn' 'en' 'ef' 'prestur' 'er' 'spurður' 'af hverju' 'samkynhneigt' 'fólk' 'má' 'ekki' 'giftast' 'þá' 'svarar' 'hann' '„' 'vegna' 'þess' 'að' 'hjónband' 'getur' 'ekki' 'átt' 'sér' 'stað' 'nema' 'á' 'milli' 'karls' 'og' 'konu' '“' '.'] | F2: IC | G2: hjónband enn rangt | H2: F | I2: IC
A3: 12695 | B3: ['Átján' 'prósent' 'fyrirtækja' 'hyggjast' 'fjölga' 'starfsfólki' 'næstu' 'þrjá' 'til' 'fjóra' 'mánuðina' 'en' 'tíu' 'prósent' 'hyggjast' 'fækka' 'því' '.'] | C3: [array([], dtype=object) array([], dtype=object) array([], dtype=object) array([], dtype=object) array([], dtype=object) array([], dtype=object) array([], dtype=object) array([], dtype=object) array([], dtype=object) array([], dtype=object) array([], dtype=object) array([], dtype=object) array([], dtype=object) array([], dtype=object) array([], dtype=object) array([], dtype=object) array([], dtype=object) array([], dtype=object)] | D3: False | E3: ['Átján' 'prósent' 'fyrirtækja' 'hyggjast' 'fjölga' 'starfsfólki' 'næstu' 'þrjá' 'til' 'fjóra' 'mánuðina' 'en' 'tíu' 'prósent' 'hyggjast' 'fækka' 'því' '.'] | F3: OK | H3: OK | I3: OK
A4: 36240 | B4: ['Klerkaveldi' 'er' 'stjórnarform' 'þar' 'sem' 'æðsti' 'valdhafi' 'er' 'sagður' 'fara' 'með' 'vald' 'Guðs' ',' 'öll' 'löggjöf' 'byggir' 'á' 'trúarbrögðum' 'og' 'á' 'að' 'tjá' 'vilja' 'Guðs' '.'] | C4: [array([], dtype=object) array([], dtype=object) array([], dtype=object) array([], dtype=object) array([], dtype=object) array([], dtype=object) array([], dtype=object) array([], dtype=object) array([], dtype=object) array([], dtype=object) array([], dtype=object) array([], dtype=object) array(['orthography', 'orthography'], dtype=object) array(['orthography', 'orthography'], dtype=object) array([], dtype=object) array([], dtype=object) array([], dtype=object) array([], dtype=object) array([], dtype=object) array([], dtype=object) array([], dtype=object) array([], dtype=object) array([], dtype=object) array([], dtype=object) array([], dtype=object) array([], dtype=object)] | D4: True | E4: ['Klerkaveldi' 'er' 'stjórnarform' 'þar' 'sem' 'æðsti' 'valdhafi' 'er' 'sagður' 'fara' 'með' 'vald' 'guðs og' 'öll' 'löggjöf' 'byggir' 'á' 'trúarbrögðum' 'og' 'á' 'að' 'tjá' 'vilja' 'Guðs' '.'] | F4: OK | G4: og bætt við | H4: OK | I4: F
A5: 36648 | B5: ['Það' 'á' 'upptök' 'sín' 'í' 'Sambíu' 'en' 'rennur' 'fyrst' 'í' 'vestur' 'til' 'Angóla' 'og' 'svo' 'aftur' 'til' 'Sambíu' 'áður' 'en' 'það' 'nær' 'Mósambík' 'þar' 'sem' 'það' 'fellur' 'í' 'Indlandshaf' '.'] | C5: [array([], dtype=object) array([], dtype=object) array([], dtype=object) array([], dtype=object) array([], dtype=object) array([], dtype=object) array([], dtype=object) array([], dtype=object) array([], dtype=object) array([], dtype=object) array([], dtype=object) array([], dtype=object) array([], dtype=object) array([], dtype=object) array([], dtype=object) array([], dtype=object) array([], dtype=object) array([], dtype=object) array([], dtype=object) array([], dtype=object) array([], dtype=object) array(['grammar'], dtype=object) array([], dtype=object) array([], dtype=object) array([], dtype=object) array([], dtype=object) array([], dtype=object) array([], dtype=object) array([], dtype=object) array([], dtype=object)] | D5: True | E5: ['Það' 'á' 'upptök' 'sín' 'í' 'Sambíu' 'en' 'rennur' 'fyrst' 'í' 'vestur' 'til' 'Angóla' 'og' 'svo' 'aftur' 'til' 'Sambíu' 'áður' 'en' 'það' 'nær' 'til' 'Mósambík' 'þar' 'sem' 'það' 'fellur' 'í' 'Indlandshaf' '.'] | F5: OK | G5: nær + til | H5: OK | I5: OK
A6: 53263 | B6: ['Sumir' 'geta' 'bara' 'alls' 'ekki' 'átt' 'peninga' 'heldur' 'verða' 'bara' 'að' 'eyða' 'þeim' '.'] | C6: [array([], dtype=object) array([], dtype=object) array([], dtype=object) array([], dtype=object) array([], dtype=object) array([], dtype=object) array([], dtype=object) array([], dtype=object) array([], dtype=object) array([], dtype=object) array([], dtype=object) array([], dtype=object) array([], dtype=object) array([], dtype=object)] | D6: False | E6: ['Sumir' 'geta' 'bara' 'alls' 'ekki' 'átt' 'peninga' 'heldur' 'verða' 'bara' 'að' 'eyða' 'þeim' '.'] | F6: OK | H6: OK | I6: OK
A7: 55379 | B7: ['Þau' 'þurftu' 'bæði' 'að' 'hafa' 'mikið' 'fyrir' 'því' 'að' 'geta' 'haldið' 'uppi' 'svo' 'stóru' 'heimili' '.'] | C7: [array([], dtype=object) array([], dtype=object) array([], dtype=object) array([], dtype=object) array([], dtype=object) array([], dtype=object) array([], dtype=object) array([], dtype=object) array([], dtype=object) array([], dtype=object) array([], dtype=object) array([], dtype=object) array([], dtype=object) array([], dtype=object) array([], dtype=object) array([], dtype=object)] | D7: False | E7: ['Þau' 'þurftu' 'bæði' 'að' 'hafa' 'mikið' 'fyrir' 'því' 'að' 'geta' 'haldið' 'uppi' 'svo' 'stóru' 'heimili' '.'] | F7: OK | H7: OK | I7: OK
A8: 30017 | B8: ['Tölvuleikjatónlist' 'er' 'yfirleitt' 'notað' 'sem' 'hugtak' 'yfir' 'bakgrunnstónlistina' 'sem' 'heyrist' 'í' 'tölvuleikjum' '.'] | C8: [array([], dtype=object) array([], dtype=object) array([], dtype=object) array([], dtype=object) array([], dtype=object) array([], dtype=object) array([], dtype=object) array(['grammar'], dtype=object) array([], dtype=object) array([], dtype=object) array([], dtype=object) array([], dtype=object) array([], dtype=object)] | D8: True | E8: ['Tölvuleikjatónlist' 'er' 'yfirleitt' 'notað' 'sem' 'hugtak' 'yfir' 'bakgrunnstónlist' 'sem' 'heyrist' 'í' 'tölvuleikjum' '.'] | F8: IC | G8: bakgrunnstónlistina -> bakgrunnstónlist | H8: F | I8: IC
A9: 2302 | B9: ['Hann' 'telur' 'að' 'um' 'fimmtán' 'manns' 'hafi' 'látið' 'af' 'störfum' 'hér' 'á' 'Íslandi' '.'] | C9: [array([], dtype=object) array([], dtype=object) array([], dtype=object) array([], dtype=object) array([], dtype=object) array([], dtype=object) array([], dtype=object) array([], dtype=object) array([], dtype=object) array([], dtype=object) array([], dtype=object) array([], dtype=object) array([], dtype=object) array([], dtype=object)] | D9: False | E9: ['Hann' 'telur' 'að' 'um' 'fimmtán' 'manns' 'hafi' 'látið' 'af' 'störfum' 'hér' 'á' 'Íslandi' '.'] | F9: OK | H9: OK | I9: OK
A10: 40825 | B10: ['Hljómsveitir' 'hafa' 'oft' 'plötusnúða' 'innan' 'raða' 'sinna' 'til' 'að' 'undirstrika' 'þessi' 'áhrif' '.'] | C10: [array([], dtype=object) array([], dtype=object) array([], dtype=object) array([], dtype=object) array([], dtype=object) array([], dtype=object) array([], dtype=object) array([], dtype=object) array([], dtype=object) array([], dtype=object) array([], dtype=object) array([], dtype=object) array([], dtype=object)] | D10: False | E10: ['Hljómsveitir' 'hafa' 'oft' 'plötusnúða' 'innan' 'raða' 'sinna' 'til' 'að' 'undirstrika' 'þessi' 'áhrif' '.'] | F10: OK | H10: OK | I10: OK
A11: 13899 | B11: ['Af' 'þessu' 'hlaust' 'talsvert' 'uppnám' 'í' 'þingsal' '.'] | C11: [array([], dtype=object) array([], dtype=object) array([], dtype=object) array([], dtype=object) array([], dtype=object) array([], dtype=object) array([], dtype=object) array([], dtype=object)] | D11: False | E11: ['Af' 'þessu' 'hlaust' 'talsvert' 'uppnám' 'í' 'þingsal' '.'] | F11: OK | H11: OK | I11: OK
A12: 34444 | B12: ['Útskýrt' 'var' 'að' 'engar' 'frekari' 'ákvarðanir' 'yrðu' 'teknar' 'um' 'viðræðurnar' 'án' 'frumkvæðis' 'þjóðarinnar' 'í' 'þjóðaratkvæðagreiðslu' '.'] | C12: [array([], dtype=object) array([], dtype=object) array([], dtype=object) array([], dtype=object) array([], dtype=object) array([], dtype=object) array([], dtype=object) array([], dtype=object) array([], dtype=object) array([], dtype=object) array([], dtype=object) array([], dtype=object) array([], dtype=object) array([], dtype=object) array([], dtype=object) array([], dtype=object)] | D12: False | E12: ['Útskýrt' 'var' 'að' 'engar' 'frekari' 'ákvarðanir' 'yrðu' 'teknar' 'um' 'viðræðurnar' 'án' 'frumkvæðis' 'þjóðarinnar' 'í' 'þjóðaratkvæðagreiðslu' '.'] | F12: OK | H12: OK | I12: OK
A13: 52229 | B13: ['Möguleikarnir' 'eru' 'endalaust' 'margir' 'sem' 'gerir' 'valið' 'enn' 'erfiðara' '.'] | C13: [array([], dtype=object) array([], dtype=object) array([], dtype=object) array([], dtype=object) array([], dtype=object) array([], dtype=object) array([], dtype=object) array([], dtype=object) array([], dtype=object) array([], dtype=object)] | D13: False | E13: ['Möguleikarnir' 'eru' 'endalaust' 'margir' 'sem' 'gerir' 'valið' 'enn' 'erfiðara' '.'] | F13: OK | H13: OK | I13: OK
A14: 35585 | B14: ['Það' 'er' 'talið' 'að' 'garðabrúða' 'sé' 'nokkuð' 'örugg' 'sé' 'hún' 'tekin' 'inn' 'í' 'litlum' 'skömmtum' 'í' 'stuttan' 'tíma' '.'] | C14: [array([], dtype=object) array([], dtype=object) array([], dtype=object) array([], dtype=object) array([], dtype=object) array([], dtype=object) array([], dtype=object) array([], dtype=object) array([], dtype=object) array([], dtype=object) array([], dtype=object) array([], dtype=object) array([], dtype=object) array([], dtype=object) array([], dtype=object) array([], dtype=object) array([], dtype=object) array([], dtype=object) array([], dtype=object)] | D14: False | E14: ['Það' 'er' 'talið' 'að' 'garðabrúða' 'sé' 'nokkuð' 'örugg' 'sé' 'hún' 'tekin' 'inn' 'í' 'litlum' 'skömmtum' 'í' 'stuttan' 'tíma' '.'] | F14: OK | H14: OK | I14: OK
A15: 32729 | B15: ['Fyrir' 'opnunarsenuna' 'á' 'hótelinu' 'þurfti' 'Sheen' 'ekkert' 'að' 'leika' 'mikið' 'þar' 'sem' 'hann' 'átti' 'afmæli' 'og' 'var' 'mjög' 'drukkinn' '.'] | C15: [array([], dtype=object) array([], dtype=object) array([], dtype=object) array([], dtype=object) array([], dtype=object) array([], dtype=object) array(['style'], dtype=object) array([], dtype=object) array([], dtype=object) array([], dtype=object) array([], dtype=object) array([], dtype=object) array([], dtype=object) array([], dtype=object) array([], dtype=object) array([], dtype=object) array([], dtype=object) array([], dtype=object) array([], dtype=object) array([], dtype=object)] | D15: True | E15: ['Fyrir' 'opnunarsenuna' 'á' 'hótelinu' 'þurfti' 'Sheen' 'ekki' 'að' 'leika' 'mikið' 'þar' 'sem' 'hann' 'átti' 'afmæli' 'og' 'var' 'mjög' 'drukkinn' '.'] | F15: OK | G15: ekkert -> ekki | H15: F | I15: F
A16: 20513 | B16: ['Kartöflur' 'á' 'norðurlandi' 'gætu' 'komið' 'eitthvað' 'síðar' 'vegna' 'veðurfars' 'þar' 'á' 'svæðinu' '.'] | C16: [array([], dtype=object) array(['style'], dtype=object) array(['style'], dtype=object) array([], dtype=object) array([], dtype=object) array([], dtype=object) array(['style'], dtype=object) array([], dtype=object) array([], dtype=object) array(['vocabulary'], dtype=object) array([], dtype=object) array(['style'], dtype=object) array([], dtype=object)] | D16: True | E16: ['Kartöflur' '' 'gætu' 'komið' 'eitthvað' 'síðar' 'á Norðurlandi' 'vegna' 'veðurfars' '' 'á' 'því svæði' '.'] | F16: IC | G16: norðurlandi er rangt í upphaflegu setningunni en annars er þetta skrýtin leiðrétting | H16: F | I16: OK
A17: 2614 | B17: ['Mats' 'Hummels' 'skoraði' 'eina' 'mark' 'leiksins' 'með' 'skalla' 'á' '13.' 'mínútu' 'en' 'hann' 'er' 'fyrsti' 'varnarmaður' 'keppninnar' 'sem' 'nær' 'að' 'skora' 'tvö' 'mörk' 'á' 'mótinu' '.'] | C17: [array([], dtype=object) array([], dtype=object) array([], dtype=object) array([], dtype=object) array([], dtype=object) array([], dtype=object) array([], dtype=object) array([], dtype=object) array([], dtype=object) array([], dtype=object) array([], dtype=object) array([], dtype=object) array([], dtype=object) array([], dtype=object) array([], dtype=object) array([], dtype=object) array([], dtype=object) array([], dtype=object) array([], dtype=object) array([], dtype=object) array([], dtype=object) array([], dtype=object) array([], dtype=object) array([], dtype=object) array([], dtype=object) array([], dtype=object)] | D17: False | E17: ['Mats' 'Hummels' 'skoraði' 'eina' 'mark' 'leiksins' 'með' 'skalla' 'á' '13.' 'mínútu' 'en' 'hann' 'er' 'fyrsti' 'varnarmaður' 'keppninnar' 'sem' 'nær' 'að' 'skora' 'tvö' 'mörk' 'á' 'mótinu' '.'] | F17: OK | H17: OK | I17: OK
A18: 36256 | B18: ['Þingið' 'getu' 'lýst' 'yfir' 'vantrausti' 'á' 'forsetan' 'og' 'leiðtoginn' 'síðan' 'svipt' 'hann' 'embætti' 'í' 'kjölfarið' '.'] | C18: [array([], dtype=object) array(['orthography'], dtype=object) array([], dtype=object) array([], dtype=object) array([], dtype=object) array([], dtype=object) array(['orthography', 'orthography'], dtype=object) array([], dtype=object) array([], dtype=object) array([], dtype=object) array([], dtype=object) array([], dtype=object) array([], dtype=object) array([], dtype=object) array([], dtype=object) array([], dtype=object)] | D18: True | E18: ['Þingið' 'getur' 'lýst' 'yfir' 'vantrausti' 'á' 'forsetann' 'og' 'leiðtoginn' 'síðan' 'svipt' 'hann' 'embætti' 'í' 'kjölfarið' '.'] | F18: OK | H18: OK | I18: OK
A19: 31454 | B19: ['Jórdanía' 'skiptist' 'í' 'tólf' 'héruð' '(' 'landstjóraumdæmi' ')' 'sem' 'aftur' 'skiptast' 'í' '54' 'umdæmi' '(' 'nawahi' ')' '.'] | C19: [array([], dtype=object) array([], dtype=object) array([], dtype=object) array([], dtype=object) array([], dtype=object) array([], dtype=object) array([], dtype=object) array([], dtype=object) array([], dtype=object) array([], dtype=object) array([], dtype=object) array([], dtype=object) array([], dtype=object) array([], dtype=object) array([], dtype=object) array([], dtype=object) array([], dtype=object) array([], dtype=object)] | D19: False | E19: ['Jórdanía' 'skiptist' 'í' 'tólf' 'héruð' '(' 'landstjóraumdæmi' ')' 'sem' 'aftur' 'skiptast' 'í' '54' 'umdæmi' '(' 'nawahi' ')' '.'] | F19: OK | H19: OK | I19: OK
A20: 685 | B20: ['Þannig' 'að' 'það' 'hefur' 'varla' 'verið' 'stórmál' '.'] | C20: [array([], dtype=object) array([], dtype=object) array([], dtype=object) array([], dtype=object) array([], dtype=object) array([], dtype=object) array([], dtype=object) array([], dtype=object)] | D20: False | E20: ['Þannig' 'að' 'það' 'hefur' 'varla' 'verið' 'stórmál' '.'] | F20: OK | H20: OK | I20: OK
A21: 3747 | B21: ['Hún' 'fékk' 'nafnið' 'Ingibjörg' 'Rósa' 'Haraldsdóttir' ',' '"' 'sagði' 'Eva' 'Laufey' 'í' 'samtali' 'við' 'Vísi' '.'] | C21: [array([], dtype=object) array([], dtype=object) array([], dtype=object) array([], dtype=object) array([], dtype=object) array([], dtype=object) array([], dtype=object) array(['orthography'], dtype=object) array([], dtype=object) array([], dtype=object) array([], dtype=object) array([], dtype=object) array([], dtype=object) array([], dtype=object) array([], dtype=object) array([], dtype=object)] | D21: True | E21: ['Hún' 'fékk' 'nafnið' 'Ingibjörg' 'Rósa' 'Haraldsdóttir' ',' '“' 'sagði' 'Eva' 'Laufey' 'í' 'samtali' 'við' 'Vísi' '.'] | F21: OK | G21: gæsalöppum breytt | H21: OK | I21: F
A22: 37045 | B22: ['Árið' '1701' '(' 'MDCCI' 'í' 'rómverskum' 'tölum' ')'] | C22: [array([], dtype=object) array([], dtype=object) array([], dtype=object) array([], dtype=object) array([], dtype=object) array([], dtype=object) array([], dtype=object) array([], dtype=object)] | D22: False | E22: ['Árið' '1701' '(' 'MDCCI' 'í' 'rómverskum' 'tölum' ')'] | F22: OK | H22: OK | I22: OK
A23: 20550 | B23: ['Hann' 'fór' 'úr' 'axlarlið' 'og' 'var' 'borinn' 'af' 'velli' '.'] | C23: [array([], dtype=object) array(['style'], dtype=object) array([], dtype=object) array([], dtype=object) array([], dtype=object) array([], dtype=object) array([], dtype=object) array([], dtype=object) array([], dtype=object) array([], dtype=object)] | D23: True | E23: ['Hann' 'hafði farið' 'úr' 'axlarlið' 'og' 'var' 'borinn' 'af' 'velli' '.'] | F23: IC | G23: fór -> hafði farið | H23: F | I23: IC
A24: 727 | B24: ['Hann' 'ætlar' 'að' 'opna' 'snemma' 'í' 'fyrramálið' 'og' 'hafa' 'opið' 'alla' 'helgina' '.'] | C24: [array([], dtype=object) array([], dtype=object) array([], dtype=object) array([], dtype=object) array([], dtype=object) array([], dtype=object) array([], dtype=object) array([], dtype=object) array([], dtype=object) array([], dtype=object) array([], dtype=object) array([], dtype=object) array([], dtype=object)] | D24: False | E24: ['Hann' 'ætlar' 'að' 'opna' 'snemma' 'í' 'fyrramálið' 'og' 'hafa' 'opið' 'alla' 'helgina' '.'] | F24: OK | H24: OK | I24: OK
A25: 42129 | B25: ['Einnig' 'tilnefndar' ':' 'Davíð' 'Logi' 'Sigurðsson' ',' 'Morgunblaðinu' ',' 'fyrir' 'skrif' 'um' 'alþjóðamál' ',' 'þar' 'á' 'meðal' 'skrif' 'um' 'Guantanamo-fangabúðirnar' 'á' 'Kúbu' 'og' 'Íslensku' 'friðargæsluna' '.'] | C25: [array([], dtype=object) array(['grammar'], dtype=object) array([], dtype=object) array([], dtype=object) array([], dtype=object) array([], dtype=object) array([], dtype=object) array([], dtype=object) array([], dtype=object) array([], dtype=object) array([], dtype=object) array([], dtype=object) array([], dtype=object) array([], dtype=object) array([], dtype=object) array([], dtype=object) array([], dtype=object) array([], dtype=object) array([], dtype=object) array([], dtype=object) array([], dtype=object) array([], dtype=object) array([], dtype=object) array([], dtype=object) array([], dtype=object) array([], dtype=object)] | D25: True | E25: ['Einnig' 'tilnefndur' ':' 'Davíð' 'Logi' 'Sigurðsson' ',' 'Morgunblaðinu' ',' 'fyrir' 'skrif' 'um' 'alþjóðamál' ',' 'þar' 'á' 'meðal' 'skrif' 'um' 'Guantanamo-fangabúðirnar' 'á' 'Kúbu' 'og' 'Íslensku' 'friðargæsluna' '.'] | F25: OK | H25: OK | I25: OK
A26: 35080 | B26: ['Var' 'mikill' 'fengur' 'að' 'því' 'að' 'fá' 'á' 'ný' 'notið' 'þessa' 'stórbrotna' 'verks' 'í' 'svo' 'vönduðum' 'flutningi' 'sem' 'hér' '.'] | C26: [array([], dtype=object) array([], dtype=object) array([], dtype=object) array([], dtype=object) array([], dtype=object) array([], dtype=object) array([], dtype=object) array([], dtype=object) array([], dtype=object) array([], dtype=object) array([], dtype=object) array([], dtype=object) array([], dtype=object) array([], dtype=object) array([], dtype=object) array([], dtype=object) array([], dtype=object) array([], dtype=object) array([], dtype=object) array([], dtype=object)] | D26: False | E26: ['Var' 'mikill' 'fengur' 'að' 'því' 'að' 'fá' 'á' 'ný' 'notið' 'þessa' 'stórbrotna' 'verks' 'í' 'svo' 'vönduðum' 'flutningi' 'sem' 'hér' '.'] | F26: OK | H26: OK | I26: OK
A27: 25848 | B27: ['Hlaupið' 'í' 'Múlakvísl' 'hófst' 'skömmu' 'fyrir' 'miðnætti' 'í' 'gærkvöldi' '.'] | C27: [array([], dtype=object) array([], dtype=object) array([], dtype=object) array([], dtype=object) array([], dtype=object) array([], dtype=object) array([], dtype=object) array([], dtype=object) array([], dtype=object) array([], dtype=object)] | D27: False | E27: ['Hlaupið' 'í' 'Múlakvísl' 'hófst' 'skömmu' 'fyrir' 'miðnætti' 'í' 'gærkvöldi' '.'] | F27: OK | H27: OK | I27: OK
A28: 3845 | B28: ['Á' 'vefsíðunni' 'fótbolti.net' 'kemur' 'fram' 'að' 'starfsmenn' 'KSÍ' 'hafði' 'þurft' 'að' 'hafa' 'hraðar' 'hendur' 'að' 'útvega' 'skó' 'í' 'gærkvöldi' '.'] | C28: [array([], dtype=object) array([], dtype=object) array([], dtype=object) array([], dtype=object) array([], dtype=object) array([], dtype=object) array([], dtype=object) array([], dtype=object) array(['grammar', 'grammar'], dtype=object) array([], dtype=object) array([], dtype=object) array([], dtype=object) array([], dtype=object) array(['grammar'], dtype=object) array([], dtype=object) array([], dtype=object) array([], dtype=object) array([], dtype=object) array([], dtype=object) array([], dtype=object)] | D28: True | E28: ['Á' 'vefsíðunni' 'fótbolti.net' 'kemur' 'fram' 'að' 'starfsmenn' 'KSÍ' 'hefðu' 'þurft' 'að' 'hafa' 'hraðar' 'hendur' 'við' 'að' 'útvega' 'skó' 'í' 'gærkvöldi' '.'] | F28: OK | H28: F | I28: OK
A29: 18378 | B29: ['Óskað' 'var' 'eftir' 'aðstoð' 'sjúkraflutningamanna' 'þegar' 'kona' 'féll' 'um' 'tvo' 'metra' 'í' 'Varmárdal' ',' 'fyrir' 'ofan' 'Reyki' ',' 'um' 'tíuleytið' 'í' 'morgun' '.'] | C29: [array([], dtype=object) array([], dtype=object) array([], dtype=object) array([], dtype=object) array([], dtype=object) array([], dtype=object) array([], dtype=object) array([], dtype=object) array([], dtype=object) array([], dtype=object) array([], dtype=object) array([], dtype=object) array([], dtype=object) array([], dtype=object) array([], dtype=object) array([], dtype=object) array([], dtype=object) array([], dtype=object) array([], dtype=object) array([], dtype=object) array([], dtype=object) array([], dtype=object) array([], dtype=object)] | D29: False | E29: ['Óskað' 'var' 'eftir' 'aðstoð' 'sjúkraflutningamanna' 'þegar' 'kona' 'féll' 'um' 'tvo' 'metra' 'í' 'Varmárdal' ',' 'fyrir' 'ofan' 'Reyki' ',' 'um' 'tíuleytið' 'í' 'morgun' '.'] | F29: OK | H29: OK | I29: OK
A30: 28198 | B30: ['Ekkert' 'bannar' 'þeim' 'þó' 'að' 'aka' 'í' 'ytri' 'hring' ',' 'en' 'í' 'mikilli' 'umferð' 'má' 'búast' 'við' 'að' 'þeir' 'valdi' 'truflun' 'og' 'óþægindum' 'fyrir' 'aðra' 'ökumenn' 'haldi' 'þeir' 'sig' 'í' 'ytri' 'akrein' 'fram' 'hjá' 'svo' 'mörgum' 'gatnamótum' '.'] | C30: [array([], dtype=object) array([], dtype=object) array([], dtype=object) array([], dtype=object) array([], dtype=object) array([], dtype=object) array([], dtype=object) array([], dtype=object) array([], dtype=object) array([], dtype=object) array([], dtype=object) array([], dtype=object) array([], dtype=object) array([], dtype=object) array([], dtype=object) array([], dtype=object) array([], dtype=object) array([], dtype=object) array([], dtype=object) array([], dtype=object) array([], dtype=object) array([], dtype=object) array([], dtype=object) array([], dtype=object) array([], dtype=object) array([], dtype=object) array([], dtype=object) array([], dtype=object) array([], dtype=object) array([], dtype=object) array([], dtype=object) array([], dtype=object) array([], dtype=object) array([], dtype=object) array([], dtype=object) array([], dtype=object) array([], dtype=object) array([], dtype=object)] | D30: False | E30: ['Ekkert' 'bannar' 'þeim' 'þó' 'að' 'aka' 'í' 'ytri' 'hring' ',' 'en' 'í' 'mikilli' 'umferð' 'má' 'búast' 'við' 'að' 'þeir' 'valdi' 'truflun' 'og' 'óþægindum' 'fyrir' 'aðra' 'ökumenn' 'haldi' 'þeir' 'sig' 'í' 'ytri' 'akrein' 'fram' 'hjá' 'svo' 'mörgum' 'gatnamótum' '.'] | F30: OK | H30: OK | I30: OK
A31: 29838 | B31: ['Meðlimir' 'hljómsveitarinnar' 'eru' 'flestir' 'mjög' 'gamlir' 'og' 'voru' 'margir' 'hættir' 'að' 'spila' 'þegar' 'þeim' 'voru' 'kallaði' 'saman' 'til' 'þessa' 'að' 'gera' 'fyrstu' 'plötuna' 'árið' '1996' '.'] | C31: [array([], dtype=object) array([], dtype=object) array([], dtype=object) array([], dtype=object) array([], dtype=object) array([], dtype=object) array([], dtype=object) array([], dtype=object) array([], dtype=object) array([], dtype=object) array([], dtype=object) array([], dtype=object) array([], dtype=object) array(['grammar'], dtype=object) array([], dtype=object) array(['grammar'], dtype=object) array([], dtype=object) array([], dtype=object) array(['grammar'], dtype=object) array([], dtype=object) array([], dtype=object) array([], dtype=object) array([], dtype=object) array([], dtype=object) array([], dtype=object) array([], dtype=object)] | D31: True | E31: ['Meðlimir' 'hljómsveitarinnar' 'eru' 'flestir' 'mjög' 'gamlir' 'og' 'voru' 'margir' 'hættir' 'að' 'spila' 'þegar' 'þeir' 'voru' 'kallaðir' 'saman' 'til' '' 'að' 'gera' 'fyrstu' 'plötuna' 'árið 1996' '.'] | F31: OK | G31: þeim -> þeir, kallaði -> kallaðir | H31: OK | I31: OK
A32: 51420 | B32: ['Vegna' 'þess' 'hve' 'góð' 'og' 'mikilvæg' 'fjárfesting' 'menntun' 'er' 'þá' 'er' 'það' 'brýn' 'nauðsyn' 'að' 'við' 'bætum' 'kerfið' 'okkar' '.'] | C32: [array([], dtype=object) array([], dtype=object) array([], dtype=object) array([], dtype=object) array([], dtype=object) array([], dtype=object) array([], dtype=object) array([], dtype=object) array(['orthography'], dtype=object) array([], dtype=object) array([], dtype=object) array([], dtype=object) array([], dtype=object) array([], dtype=object) array([], dtype=object) array([], dtype=object) array([], dtype=object) array([], dtype=object) array([], dtype=object) array([], dtype=object)] | D32: True | E32: ['Vegna' 'þess' 'hve' 'góð' 'og' 'mikilvæg' 'fjárfesting' 'menntun' 'er' ',' 'þá' 'er' 'það' 'brýn' 'nauðsyn' 'að' 'við' 'bætum' 'kerfið' 'okkar' '.'] | F32: IC | H32: F | I32: F
A33: 264 | B33: ['Guðjón' 'tók' 'við' 'starfi' 'knattspyrnustjóra' 'hjá' 'Grindavík' 'í' 'nóvember' '2011' '.'] | C33: [array([], dtype=object) array([], dtype=object) array([], dtype=object) array([], dtype=object) array([], dtype=object) array([], dtype=object) array([], dtype=object) array([], dtype=object) array([], dtype=object) array([], dtype=object) array([], dtype=object)] | D33: False | E33: ['Guðjón' 'tók' 'við' 'starfi' 'knattspyrnustjóra' 'hjá' 'Grindavík' 'í' 'nóvember' '2011' '.'] | F33: OK | H33: OK | I33: OK
A34: 56915 | B34: ['Morgunblaðið' ',' 'DV' 'og' 'Séð' 'og' 'heyrt' ')' 'og' 'Internetið' '.'] | C34: [array([], dtype=object) array([], dtype=object) array([], dtype=object) array([], dtype=object) array([], dtype=object) array([], dtype=object) array([], dtype=object) array(['orthography'], dtype=object) array([], dtype=object) array([], dtype=object) array([], dtype=object)] | D34: True | E34: ['Morgunblaðið' ',' 'DV' 'og' 'Séð' 'og' 'heyrt' '' 'og' 'Internetið' '.'] | F34: OK | G34: eina villan hér er ) | H34: OK | I34: OK
A35: 46983 | B35: ['Þeir' 'finna' 'Ófeig' 'særðan' 'eftir' 'árás' 'þrjótanna' '.'] | C35: [array([], dtype=object) array([], dtype=object) array(['style'], dtype=object) array([], dtype=object) array([], dtype=object) array([], dtype=object) array([], dtype=object) array([], dtype=object)] | D35: True | E35: ['Þeir' 'finna' 'Ófeig' 'særðan' 'eftir' 'árás' 'þrjótanna' '.'] | F35: IC | G35: engin breyting??? | H35: F | I35: IC
A36: 43861 | B36: ['Harðlínu' 'kommúnismi' 'var' 'þó' 'aldrei' 'allsráðandi' ',' 'til' 'dæmis' 'voru' 'tilraunir' 'til' 'að' 'koma' 'á' 'samyrkjubúum' 'fljótlega' 'lagðar' 'af' '.'] | C36: [array(['orthography'], dtype=object) array(['orthography'], dtype=object) array([], dtype=object) array([], dtype=object) array([], dtype=object) array([], dtype=object) array([], dtype=object) array([], dtype=object) array([], dtype=object) array([], dtype=object) array([], dtype=object) array([], dtype=object) array([], dtype=object) array([], dtype=object) array([], dtype=object) array([], dtype=object) array([], dtype=object) array([], dtype=object) array([], dtype=object) array([], dtype=object)] | D36: True | E36: ['Harðlínukommúnismi' 'var' 'þó' 'aldrei' 'allsráðandi' ',' 'til' 'dæmis' 'voru' 'tilraunir' 'til' 'að' 'koma' 'á' 'samyrkjubúum' 'fljótlega' 'lagðar' 'af' '.'] | F36: OK | G36: harðlínu kommúnismi -> eitt orð | H36: OK | I36: OK
